Workbook
Name Acquirer_Name: 'Synergy Calc'!$D$2
Name Basic_Shares: 'Share Dilution Calc'!$H$7
Name Beta: WACC!$F$10
Name Company_Name: 'AVAV-DCF'!$D$7
Name Comps_Range: 'Share Dilution Calc'!$D$1:$H$33
Name Cost_of_Debt: WACC!$F$8
Name Cost_of_Preferred: WACC!$F$9
Name Equity_Risk_Premium: WACC!$F$7
Name Final_Discount_Rate: 'AVAV-DCF'!#REF!
Name Forward_Year_1: Inputs!$E$7
Name Forward_Year_2: Inputs!$E$8
Name Forward_Year_3: Inputs!$E$9
Name FYear_1_Name: Inputs!$B$7
Name FYear_2_Name: Inputs!$B$8
Name FYear_3_Name: Inputs!$B$9
Name Hist_Year: 'AVAV-DCF'!$K$7
Name Initial_Discount_Rate: 'AVAV-DCF'!#REF!
Name JZP110_Risk_Adjustment_Factor: 'AVAV-DCF'!#REF!
Name LTM: Inputs!$E$6
Name LTM_Name: Inputs!$B$6
Name Next_Year: 'AVAV-DCF'!$K$8
Name Num_Years: 'AVAV-DCF'!#REF!
Name Risk_Free_Rate: WACC!$F$6
Name Scenario: 'AVAV-DCF'!$D$14
Name Share_Price: 'AVAV-DCF'!$D$11
Name Stub_Period: 'AVAV-DCF'!#REF!
Name Tax_Rate: 'AVAV-DCF'!$D$12
Name Terminal_Growth_Rate: 'AVAV-DCF'!$N$92
Name Terminal_Multiple: 'AVAV-DCF'!$G$92
Name Ticker: 'AVAV-DCF'!$D$8
Name Units: 'AVAV-DCF'!$D$9
Name Valuation_Date: 'AVAV-DCF'!$K$9
Name Vyxeos_Risk_Adjustment_Factor: 'AVAV-DCF'!#REF!
Name WACC: WACC!$L$45
Name Year_Remaining_Pct: 'AVAV-DCF'!#REF!

Sheet AVAV-DCF
B2: =Company_Name&" - Operating Model and DCF Analysis - "&Scenario&" Case" -> AeroVironment, Inc. - Operating Model and DCF Analysis - Base Case
B3: ($ in Thousands Except Per Share and Per Unit Data)
B5: Assumptions: | Q5: Base
Q6: Upside
C7: Company Name: | D7: AeroVironment, Inc. | H7: Last Fiscal Year: | K7: 45777 | Q7: Downside
C8: Ticker: | D8: AVAV | H8: Next Fiscal Year: | K8: =EOMONTH(Hist_Year,12) -> 46142
C9: Units (for Conversions): | D9: 1000 | H9: Current Valuation Date: | K9: 45962
C11: Current Share Price: | D11: 369.91
C12: Effective Tax Rate: | D12: 0.16655
C14: Selected Scenario: | D14: Base
F17: Historical | J17: Projected
B18: Revenue Assumptions: | D18: Units: | E18: =EOMONTH(F18,-12) -> 44316 | F18: =EOMONTH(G18,-12) -> 44681 | G18: =EOMONTH(H18,-12) -> 45046 | H18: =EOMONTH(I18,-12) -> 45412 | I18: =Hist_Year -> 45777 | J18: =EOMONTH(I18,12) -> 46142 | K18: =EOMONTH(J18,12) -> 46507 | L18: =EOMONTH(K18,12) -> 46873 | M18: =EOMONTH(L18,12) -> 47238 | N18: =EOMONTH(M18,12) -> 47603
C20: LMS Assumptions: | E20: =$E$18 -> 44316 | F20: =$F$18 -> 44681 | G20: =$G$18 -> 45046 | H20: =$H$18 -> 45412 | I20: =$I$18 -> 45777 | J20: =$J$18 -> 46142 | K20: =$K$18 -> 46507 | L20: =$L$18 -> 46873 | M20: =$M$18 -> 47238 | N20: =$N$18 -> 47603
C22: Revenue | D22: $ '000 | E22: =87268 -> 87268 | F22: =76415 -> 76415 | G22: 120624 | H22: 192587 | I22: 351977 | J22: =I22*(1+J23) -> 1055931 | K22: =J22*(1+K23) -> 1478303.4 | L22: =K22*(1+L23) -> 1921794.4 | M22: =L22*(1+M23) -> 2306153.3 | N22: =M22*(1+N23) -> 2652076.3
C23: % growth | D23: % | F23: =F22/E22 - 1 -> -0.12436403 | G23: =G22/F22 - 1 -> 0.57853825 | H23: =H22/G22 - 1 -> 0.5965894 | I23: =I22/H22 - 1 -> 0.82762596 | J23: =INDEX(J24:J26, MATCH(Scenario, $C24:$C26, 0)) -> 2 | K23: =INDEX(K24:K26, MATCH(Scenario, $C24:$C26, 0)) -> 0.4 | L23: =INDEX(L24:L26, MATCH(Scenario, $C24:$C26, 0)) -> 0.3 | M23: =INDEX(M24:M26, MATCH(Scenario, $C24:$C26, 0)) -> 0.2 | N23: =INDEX(N24:N26, MATCH(Scenario, $C24:$C26, 0)) -> 0.15
C24: Base | D24: % | J24: 2 | K24: 0.4 | L24: 0.3 | M24: 0.2 | N24: 0.15
C25: Upside | D25: % | J25: 2.5 | K25: 0.5 | L25: 0.4 | M25: 0.3 | N25: 0.2
C26: Downside | D26: % | J26: 1.5 | K26: 0.2 | L26: 0.1 | M26: 0.05 | N26: 0.05
C28: Cost of Sales | D28: $ '000 | E28: =87268-26675 -> 60593 | F28: =76415-24486 -> 51929 | G28: 77888 | H28: 124363 | I28: 223422 | J28: =J29*J22 -> 612439.98 | K28: =K29*K22 -> 827849.9 | L28: =L29*L22 -> 1037769 | M28: =M29*M22 -> 1199199.7 | N28: =N29*N22 -> 1326038.1
C29: % revenue | D29: % | E29: =E28/E22 -> 0.6943324 | F29: =F28/F22 -> 0.67956553 | G29: =G28/G22 -> 0.64570898 | H29: =H28/H22 -> 0.64574971 | I29: =I28/I22 -> 0.63476307 | J29: =INDEX(J30:J32, MATCH(Scenario, $C30:$C32, 0)) -> 0.58 | K29: =INDEX(K30:K32, MATCH(Scenario, $C30:$C32, 0)) -> 0.56 | L29: =INDEX(L30:L32, MATCH(Scenario, $C30:$C32, 0)) -> 0.54 | M29: =INDEX(M30:M32, MATCH(Scenario, $C30:$C32, 0)) -> 0.52 | N29: =INDEX(N30:N32, MATCH(Scenario, $C30:$C32, 0)) -> 0.5
C30: Base | D30: % | J30: 0.58 | K30: 0.56 | L30: 0.54 | M30: 0.52 | N30: 0.5
C31: Upside | D31: % | J31: 0.55 | K31: 0.52 | L31: 0.5 | M31: 0.48 | N31: 0.46
C32: Downside | D32: % | J32: 0.6 | K32: 0.58 | L32: 0.56 | M32: 0.54 | N32: 0.54
C34: UwS Assumptions: | E34: =$E$18 -> 44316 | F34: =$F$18 -> 44681 | G34: =$G$18 -> 45046 | H34: =$H$18 -> 45412 | I34: =$I$18 -> 45777 | J34: =$J$18 -> 46142 | K34: =$K$18 -> 46507 | L34: =$L$18 -> 46873 | M34: =$M$18 -> 47238 | N34: =$N$18 -> 47603
C36: Revenue | D36: $ '000 | E36: =235854+15837 -> 251691 | F36: =178201+93156 -> 271357 | G36: 343910 | H36: 448006 | I36: 381778 | J36: =I36*(1+J37) -> 725378.2 | K36: =J36*(1+K37) -> 906722.75 | L36: =K36*(1+L37) -> 1088067.3 | M36: =L36*(1+M37) -> 1251277.4 | N36: =M36*(1+N37) -> 1376405.1
C37: Growth | D37: % | F37: =F36/E36 - 1 -> 0.078135492 | G37: =G36/F36 - 1 -> 0.26737103 | H37: =H36/G36 - 1 -> 0.30268384 | I37: =I36/H36 - 1 -> -0.14782838 | J37: =INDEX(J38:J40, MATCH(Scenario, $C38:$C40, 0)) -> 0.9 | K37: =INDEX(K38:K40, MATCH(Scenario, $C38:$C40, 0)) -> 0.25 | L37: =INDEX(L38:L40, MATCH(Scenario, $C38:$C40, 0)) -> 0.2 | M37: =INDEX(M38:M40, MATCH(Scenario, $C38:$C40, 0)) -> 0.15 | N37: =INDEX(N38:N40, MATCH(Scenario, $C38:$C40, 0)) -> 0.1
C38: Base | D38: % | J38: 0.9 | K38: 0.25 | L38: 0.2 | M38: 0.15 | N38: 0.1
C39: Upside | D39: % | J39: 1.1 | K39: 0.3 | L39: 0.25 | M39: 0.2 | N39: 0.15
C40: Downside | D40: % | J40: 0.7 | K40: 0.2 | L40: 0.1 | M40: 0.05 | N40: 0.05
C42: Cost of Sales | D42: $ '000 | E42: =251691-(119062+2965) -> 129664 | F42: =271357-(83759+6155) -> 181443 | G42: =231960-12731 -> 219229 | H42: =249763-12280 -> 237483 | I42: =213133-18480 -> 194653 | J42: =J43*J36 -> 449734.48 | K42: =K43*K36 -> 544033.65 | L42: =L43*L36 -> 631079.03 | M42: =M43*M36 -> 713228.12 | N42: =N43*N36 -> 770786.88
C43: % revenue | D43: % | E43: =E42/E36 -> 0.51517138 | F43: =F42/F36 -> 0.66865052 | G43: =G42/G36 -> 0.63746038 | H43: =H42/H36 -> 0.53008888 | I43: =I42/I36 -> 0.50985913 | J43: =INDEX(J44:J46, MATCH(Scenario, $C44:$C46, 0)) -> 0.62 | K43: =INDEX(K44:K46, MATCH(Scenario, $C44:$C46, 0)) -> 0.6 | L43: =INDEX(L44:L46, MATCH(Scenario, $C44:$C46, 0)) -> 0.58 | M43: =INDEX(M44:M46, MATCH(Scenario, $C44:$C46, 0)) -> 0.57 | N43: =INDEX(N44:N46, MATCH(Scenario, $C44:$C46, 0)) -> 0.56
C44: Base | D44: % | J44: 0.62 | K44: 0.6 | L44: 0.58 | M44: 0.57 | N44: 0.56
C45: Upside | D45: % | J45: 0.6 | K45: 0.58 | L45: 0.55 | M45: 0.53 | N45: 0.52
C46: Downside | D46: % | J46: 0.64 | K46: 0.63 | L46: 0.62 | M46: 0.61 | N46: 0.6
C48: MW Assumptions: | E48: =$E$18 -> 44316 | F48: =$F$18 -> 44681 | G48: =$G$18 -> 45046 | H48: =$H$18 -> 45412 | I48: =$I$18 -> 45777 | J48: =$J$18 -> 46142 | K48: =$K$18 -> 46507 | L48: =$L$18 -> 46873 | M48: =$M$18 -> 47238 | N48: =$N$18 -> 47603
C50: Revenue | D50: $ '000 | E50: =13527 -> 13527 | F50: =54365 -> 54365 | G50: 76002 | H50: 76127 | I50: 86782 | J50: =I50*(1+J51) -> 121494.8 | K50: =J50*(1+K51) -> 139719.02 | L50: =K50*(1+L51) -> 153690.92 | M50: =L50*(1+M51) -> 165217.74 | N50: =M50*(1+N51) -> 173478.63
C51: Growth | D51: % | F51: =F50/E50 - 1 -> 3.018999 | G51: =G50/F50 - 1 -> 0.39799503 | H51: =H50/G50 - 1 -> 0.0016446936 | I51: =I50/H50 - 1 -> 0.13996348 | J51: =INDEX(J52:J54, MATCH(Scenario, $C52:$C54, 0)) -> 0.4 | K51: =INDEX(K52:K54, MATCH(Scenario, $C52:$C54, 0)) -> 0.15 | L51: =INDEX(L52:L54, MATCH(Scenario, $C52:$C54, 0)) -> 0.1 | M51: =INDEX(M52:M54, MATCH(Scenario, $C52:$C54, 0)) -> 0.075 | N51: =INDEX(N52:N54, MATCH(Scenario, $C52:$C54, 0)) -> 0.05
C52: Base | D52: % | J52: 0.4 | K52: 0.15 | L52: 0.1 | M52: 0.075 | N52: 0.05
C53: Upside | D53: % | J53: 0.6 | K53: 0.25 | L53: 0.2 | M53: 0.15 | N53: 0.1
C54: Downside | D54: % | J54: 0.2 | K54: 0.15 | L54: 0.1 | M54: 0.05 | N54: 0.05
...

Sheet A_D
C2: Acquirer: | D2: Target: | E2: Pro | G2: Deal
C3: KTOS | D3: AVAV | E3: Forma (Year 1) | G3: Assumptions:
B5: Acquirer | G5: Deal date: | H5: =Valuation_Date -> 45962
B6: Current share price | C6: 90.6
B7: Diluted shares outstanding | C7: 172900000 | G7: Form of consideration
B8: 2026 Earnings per share (EPS) forecast | C8: 0.13 | G8: % Stock | H8: 0.5
B9: Acquirer shares issued in transaction | C9: =H8*D16/C6 -> 58172386 | G9: % Cash | H9: =1-H8 -> 0.5 | I9: <--Assume cash portion financed entirely by new acquirer debt for simplicity of this exercise.
B11: Target | G11: Tax rate: | H11: 0.27 | I11: <--Effective Tax Rate of KTOS
B12: Pre-deal share price | D12: =Share_Price -> 369.91
B13: Offer price per share | D13: ='AVAV-DCF'!N116 -> 224.83592 | G13: Deal debt:
B14: % Offer Premium | D14: =D13/D12-1 -> -0.39218751 | G14: Acquirer new borrowing | H14: =D16*H9 -> 5.2704181e+09
B15: Shares outstanding | D15: 46882350 | G15: Term of loan | H15: 5
B16: Offer value | D16: =D13*D15 -> 1.0540836e+10 | G16: Interest rate on new debt | H16: 0.05
B17: 2026 Earnings per share (EPS) forecast | D17: ='AVAV-DCF'!J192*Units/A_D!D15 -> 6.5606331 | G17: Financing fees | H17: =0.03%*H14 -> 1581125.4 | I17: <--0.03% of the Loan Value
G18: Annual financing fee amortization | H18: =H17/H15 -> 316225.09
B19: Accretion / dilution analysis
B20: Implied standalone net income | C20: =C8*C7 -> 22477000 | D20: =D17*D15 -> 307577896 | G20: Synergies: | H20: ='Synergy Calc'!E75*Units*Units -> 1.6018596e+08
B21: Implied standalone pretax income | C21: =C20/(1-$H$11) -> 30790411 | D21: =D20/(1-$H$11) -> 4.2133958e+08
G22: Deal fees: | H22: =0.5%*D16 -> 52704181 | I22: <--0.5% of the Transaction Value
B23: Pro forma pretax income - unadjusted | E23: =C21+D21 -> 4.5212999e+08
B24: Less: Interest expense from new deal debt | E24: =-H16*H14 -> -2.6352091e+08
B25: Less: Deal fees | E25: =-H22 -> -52704181
B26: Less: Financing fees amortization | E26: =-H18 -> -316225.09
B27: Plus: Synergies | E27: =H20 -> 1.6018596e+08
B28: Pro forma pretax income - adjusted | E28: =SUM(E23:E27) -> 2.9577464e+08
B30: Pro Forma Net Income | E30: =E28*(1-H11) -> 2.1591549e+08
B31: Pro Forma Shares Outstanding | E31: =C7+C9 -> 2.3107239e+08
B33: Pro Forma EPS | E33: =E30/E31 -> 0.93440628
B34: Acquirer standalone EPS | E34: =C8 -> 0.13
B35: Accretion / Dilution per share | E35: =E33-E34 -> 0.80440628
B36: Accretion / Dilution % | E36: =E33/E34-1 -> 6.1877407
B39: Sensitivity analysis
B40: Accretion / dilution sensitivity at various % consideration and $ offer price per share assumptions
D41: % stock:
C42: =E35 -> 0.80440628 | D42: 0 | E42: 0.5 | F42: 1
B43: Offer price: | C43: 30 | D43: 1.299871 | E43: 1.2241859 | F43: 1.1514569
C44: 40 | D44: 0.99503226 | E44: 0.90282663 | F44: 0.81536108
C45: 70 | D45: 0.080516129 | E45: -0.03631044 | F45: -0.14301709

Sheet H1-Results
B2: =Company_Name&" - H1 Financial Results" -> AeroVironment, Inc. - H1 Financial Results
B3: ='AVAV-DCF'!$B$3 -> ($ in Thousands Except Per Share and Per Unit Data)
B6: Reported Income Statement and Cash Flow Statement Figures from H1: | D6: FY26 - H1
C7: Revenue: | D7: 927184
C8: Annual Revenue Growth Rate: | D8: =D7/377941 - 1 -> 1.4532506
C9: Operating Income (EBIT): | D9: =D7-727961-229612-69107 -> -99496
C10: Annual Operating Margin: | D10: =+D9/D7 -> -0.10730988
C12: (-) Taxes, Excluding Effect of Interest: | D12: =-17474 + (G12*17474/104930) -> -16569.076 | G12: =12746-7312 -> 5434
C14: Net Operating Profit After Tax (NOPAT): | D14: =+D9-D12 -> -82926.924
C16: Adjustments for Non-Cash Charges:
C17: (+) Intangible Asset Amortization: | D17: =127881+31985+2240 -> 162106
C18: (+) Depreciation: | D18: 20446
C19: (+/-) Deferred Income Taxes: | D19: 0
C20: (+/-) Other Items: | D20: =19995-1538 -> 18457
C21: Total Adjustments for Non-Cash Charges: | D21: =SUM(D17:D20) -> 201009
C23: Changes in Operating Assets & Liabilities:
C24: Accounts Receivable: | D24: -51519
C25: Inventories: | D25: -49360
C26: Prepaid Expenses and Other Current Assets: | D26: -12747
C27: Accounts Payable: | D27: -7772
C28: Income Taxes receivable: | D28: -22230
C29: Unbilled receivables and retentions: | D29: -124417
C30: Other Liabilities: | D30: -2106
C31: Total Changes in Operating Assets & Liabilities: | D31: =SUM(D24:D30) -> -270151
C33: (-) Capital Expenditures: | D33: -46803
C35: H1 Unlevered Free Cash Flow: | D35: =+D14+D21+D31+D33 -> -198871.92

Sheet D&A Schedule
F1: 1
B2: 2 | C2: =CHOOSE(B2, "as a % of revenue", "as a % of PPE") -> as a % of PPE | F2: 2
B4: (in thousands)
B5: PP&E Schedule: | C5: FY21 | D5: FY22 | E5: FY23 | F5: FY24 | G5: FY25 | H5: FY26 | I5: FY27 | J5: FY28 | K5: FY29 | L5: FY30
B6: Beginning PP&E | D6: =C11 -> 58896 | E6: =D11 -> 62296 | F6: =E11 -> 39795 | G6: =F11 -> 46602 | H6: =G11 -> 50704 | I6: =H11 -> 54760.32 | J6: =I11 -> 61331.558 | K6: =J11 -> 71144.608 | L6: =K11 -> 84662.083
B7: Depreciation | D7: 30493 | E7: 41803 | F7: 17098 | G7: 17063 | H7: =CHOOSE($B$2, H8*'AVAV-DCF'!J$134, H8*H$6) -> 20281.6 | I7: =CHOOSE($B$2, I8*'AVAV-DCF'!K$134, I8*I$6) -> 20808.922 | J7: =CHOOSE($B$2, J8*'AVAV-DCF'!L$134, J8*J$6) -> 22079.361 | K7: =CHOOSE($B$2, K8*'AVAV-DCF'!M$134, K8*K$6) -> 24900.613 | L7: =CHOOSE($B$2, L8*'AVAV-DCF'!N$134, L8*L$6) -> 29631.729
B8: =$C$2 -> as a % of PPE | D8: =CHOOSE($B$2, D7/'AVAV-DCF'!F$134, 'D&A Schedule'!D7/'D&A Schedule'!D$6) -> 0.51774314 | E8: =CHOOSE($B$2, E7/'AVAV-DCF'!G$134, 'D&A Schedule'!E7/'D&A Schedule'!E$6) -> 0.67103827 | F8: =CHOOSE($B$2, F7/'AVAV-DCF'!H$134, 'D&A Schedule'!F7/'D&A Schedule'!F$6) -> 0.42965197 | G8: =CHOOSE($B$2, G7/'AVAV-DCF'!I$134, 'D&A Schedule'!G7/'D&A Schedule'!G$6) -> 0.36614308 | H8: =CHOOSE($B$2, 1%, 40%) -> 0.4 | I8: =CHOOSE($B$2, 1.25%, 38%) -> 0.38 | J8: =CHOOSE($B$2, 1.5%,36%) -> 0.36 | K8: =CHOOSE($B$2, 1.5%, 35%) -> 0.35 | L8: =CHOOSE($B$2, 1.5%, 35%) -> 0.35
B9: Capex | D9: =D11-D6+D7 -> 33893 | E9: =E11-E6+E7 -> 19302 | F9: =F11-F6+F7 -> 23905 | G9: =G11-G6+G7 -> 21165 | H9: =CHOOSE($B$2, H10*'AVAV-DCF'!J$134, H10*H$6) -> 24337.92 | I9: =CHOOSE($B$2, I10*'AVAV-DCF'!K$134, I10*I$6) -> 27380.16 | J9: =CHOOSE($B$2, J10*'AVAV-DCF'!L$134, J10*J$6) -> 31892.41 | K9: =CHOOSE($B$2, K10*'AVAV-DCF'!M$134, K10*K$6) -> 38418.088 | L9: =CHOOSE($B$2, L10*'AVAV-DCF'!N$134, L10*L$6) -> 46564.146
B10: =$C$2 -> as a % of PPE | D10: =CHOOSE($B$2, D9/'AVAV-DCF'!F$134, 'D&A Schedule'!D9/'D&A Schedule'!D$6) -> 0.57547202 | E10: =CHOOSE($B$2, E9/'AVAV-DCF'!G$134, 'D&A Schedule'!E9/'D&A Schedule'!E$6) -> 0.30984333 | F10: =CHOOSE($B$2, F9/'AVAV-DCF'!H$134, 'D&A Schedule'!F9/'D&A Schedule'!F$6) -> 0.60070361 | G10: =CHOOSE($B$2, G9/'AVAV-DCF'!I$134, 'D&A Schedule'!G9/'D&A Schedule'!G$6) -> 0.45416506 | H10: =CHOOSE($B$2, 1.25%, 48%) -> 0.48 | I10: =CHOOSE($B$2, 1.5%, 50%) -> 0.5 | J10: =CHOOSE($B$2, 1.75%,52%) -> 0.52 | K10: =CHOOSE($B$2,1.75%, 54%) -> 0.54 | L10: =CHOOSE($B$2, 1.75%, 55%) -> 0.55
B11: Ending Value (PPE) | C11: 58896 | D11: 62296 | E11: 39795 | F11: 46602 | G11: 50704 | H11: =H6-H7+H9 -> 54760.32 | I11: =I6-I7+I9 -> 61331.558 | J11: =J6-J7+J9 -> 71144.608 | K11: =K6-K7+K9 -> 84662.083 | L11: =L6-L7+L9 -> 101594.5

Sheet Share Dilution Calc
A1: 1 | H1: =Ticker -> AVAV
A2: =A1+1 -> 2 | H2: =Company_Name -> AeroVironment, Inc.
A3: =A2+1 -> 3 | E3: Calendarization:
A4: =A3+1 -> 4 | E4: 42551 | F4: 42916 | G4: 42735 | H4: =+F4 -> 42916
A5: =#REF!+1 -> #REF! | E5: Diluted Shares Calculations:
A6: =A5+1 -> #REF! | B6: Share Price as of the Valuation Date: | H6: 369.91
A7: =A6+1 -> #REF! | B7: Common Shares Outstanding: | H7: 49.927306
A8: =A7+1 -> #REF! | B8: Options and Warrants:
A9: =A8+1 -> #REF! | F9: Total | G9: Strike | H9: Dilution
A10: =A9+1 -> #REF! | F10: =2.614416+2.66141 -> 5.275826 | G10: 280 | H10: =IF(G10<H$6,F10-((F10*G10)/H$6),0) -> 1.2823376
A11: =A10+1 -> #REF! | H11: =IF(G11<H$6,F11-((F11*G11)/H$6),0) -> 0
A12: =A11+1 -> #REF! | H12: =IF(G12<H$6,F12-((F12*G12)/H$6),0) -> 0
A13: =A12+1 -> #REF! | H13: =IF(G13<H$6,F13-((F13*G13)/H$6),0) -> 0
A14: =A13+1 -> #REF! | H14: =IF(G14<H$6,F14-((F14*G14)/H$6),0) -> 0
A15: =A14+1 -> #REF! | H15: =IF(G15<H$6,F15-((F15*G15)/H$6),0) -> 0
A16: =A15+1 -> #REF! | H16: =IF(G16<H$6,F16-((F16*G16)/H$6),0) -> 0
A17: =A16+1 -> #REF! | H17: =IF(G17<H$6,F17-((F17*G17)/H$6),0) -> 0
A18: =A17+1 -> #REF! | H18: =IF(G18<H$6,F18-((F18*G18)/H$6),0) -> 0
A19: =A18+1 -> #REF!
A20: =A19+1 -> #REF! | B20: Convertible Bonds: | E20: $ Amount | F20: Par Value | G20: Conv. Price | H20: Dilution
A21: =A20+1 -> #REF! | E21: 747.5 | F21: 1000 | G21: 322.4 | H21: =IFERROR(IF(G21>H$6,0,(+F21/G21)*E21/F21),0) -> 2.3185484
A22: =A21+1 -> #REF! | H22: =IFERROR(IF(G22>H$6,0,(+F22/G22)*E22/F22),0) -> 0
A23: =A22+1 -> #REF!
A24: =A23+1 -> #REF! | G24: # RSUs | H24: Dilution
A25: =A24+1 -> #REF! | B25: Restricted Stock Units (RSUs): | G25: 0.37416 | H25: =+G25 -> 0.37416
A26: =A25+1 -> #REF!
A27: =A26+1 -> #REF! | B27: Total Diluted Shares: | H27: =+H25+SUM(H10:H18)+SUM(H21:H22)+H7 -> 53.902352
A28: =A27+1 -> #REF!
A29: =A28+1 -> #REF! | E29: Valuation Metrics:
A30: =A29+1 -> #REF!
A31: =A30+1 -> #REF! | B31: Equity Value: | H31: =+H27*H6 -> 19939.019
A32: =A31+1 -> #REF! | B32: Enterprise Value: | H32: =+H31+SUM(#REF!) -> #REF!
A33: =A32+1 -> #REF! | B33: Beta:

Sheet WACC
B2: ="WACC Analysis - "&TEXT(Company_Name,"") -> WACC Analysis - AeroVironment, Inc.
B3: =+'AVAV-DCF'!$B$3 -> ($ in Thousands Except Per Share and Per Unit Data)
B5: Discount Rate Calculations - Assumptions:
B6: Risk-Free Rate: | F6: 0.0412
B7: Equity Risk Premium: | F7: 0.055
B8: Pre-Tax Cost of Debt: | F8: 0.0595
B9: Cost of Preferred Stock: | F9: 0
B10: Historical Beta (2-year Levered Beta): | F10: 1.65
B12: =+Inputs!#REF! -> #REF! | D12: =+Inputs!#REF! -> #REF! | E12: =+Inputs!#REF! -> #REF! | G12: =+Inputs!#REF! -> #REF! | I12: =+Inputs!#REF! -> #REF! | K12: =+Inputs!#REF! -> #REF!
B13: Comparable Companies - Unlevered Beta Calculation:
D14: Levered | G14: Preferred | I14: Equity | K14: Effective Tax Rate | L14: Unlevered
B15: Name | C15: Ticker | D15: Beta | E15: Debt | F15: % Debt | G15: Stock | H15: % Preferred | I15: Value | J15: % Equity | L15: Beta
B16: ='Public Comps'!B9 -> Heico Corporation | C16: ='Public Comps'!C9 -> HEI | D16: 0.9 | E16: 1150 | F16: 0.036 | G16: 0 | H16: 0 | I16: 30500 | J16: 0.964 | K16: 0.23 | L16: =D16/(1+(F16/J16)*(1-K16)) -> 0.87484371
B17: ='Public Comps'!B10 -> Teledyne Technologies Inc. | C17: ='Public Comps'!C10 -> TDY | D17: 1.05 | E17: 3900 | F17: 0.172 | G17: 0 | H17: 0 | I17: 18800 | J17: 0.828 | K17: 0.21 | L17: =D17/(1+(F17/J17)*(1-K17)) -> 0.9019795
B18: ='Public Comps'!B11 -> Curtiss-Wright Corporation | C18: ='Public Comps'!C11 -> CW | D18: 1.1 | E18: 950 | F18: 0.076 | G18: 0 | H18: 0 | I18: 11600 | J18: 0.924 | K18: 0.22 | L18: =D18/(1+(F18/J18)*(1-K18)) -> 1.0336832
B19: ='Public Comps'!B12 -> Textron Inc. | C19: ='Public Comps'!C12 -> TXT | D19: 1.35 | E19: 5400 | F19: 0.249 | G19: 0 | H19: 0 | I19: 16300 | J19: 0.751 | K19: 0.23 | L19: =D19/(1+(F19/J19)*(1-K19)) -> 1.0754405
B20: ='Public Comps'!B13 -> Kratos Defense & Security Solutions, Inc. | C20: ='Public Comps'!C13 -> KTOS | D20: 1.4 | E20: 350 | F20: 0.084 | G20: 0 | H20: 0 | I20: 3800 | J20: 0.916 | K20: 0.21 | L20: =D20/(1+(F20/J20)*(1-K20)) -> 1.3054277
B21: ='Public Comps'!B14 -> Huntington Ingalls Industries, Inc. | C21: ='Public Comps'!C14 -> HII | D21: 1.2 | E21: 2800 | F21: 0.301 | G21: 0 | H21: 0 | I21: 6500 | J21: 0.699 | K21: 0.22 | L21: =D21/(1+(F21/J21)*(1-K21)) -> 0.89828439
B22: ='Public Comps'!B15 -> Hexcel Corporation | C22: ='Public Comps'!C15 -> HXL | D22: 1.45 | E22: 1150 | F22: 0.211 | G22: 0 | H22: 0 | I22: 4300 | J22: 0.789 | K22: 0.23 | L22: =D22/(1+(F22/J22)*(1-K22)) -> 1.2024026
B23: ='Public Comps'!B16 -> Spirit Aerosystems Holdigns, Inc. | C23: ='Public Comps'!C16 -> SPR | D23: 2.1 | E23: 4200 | F23: 0.575 | G23: 0 | H23: 0 | I23: 3100 | J23: 0.425 | K23: 0.25 | L23: =D23/(1+(F23/J23)*(1-K23)) -> 1.0423358
B24: ='Public Comps'!B17 -> AAR Corporation | C24: ='Public Comps'!C17 -> AIR | D24: 1.3 | E24: 1050 | F24: 0.304 | G24: 0 | H24: 0 | I24: 2400 | J24: 0.696 | K24: 0.24 | L24: =D24/(1+(F24/J24)*(1-K24)) -> 0.97600967
B25: ='Public Comps'!B18 -> Astronics Corporation | C25: ='Public Comps'!C18 -> ATRO | D25: 1.6 | E25: 190 | F25: 0.209 | G25: 0 | H25: 0 | I25: 720 | J25: 0.791 | K25: 0.23 | L25: =D25/(1+(F25/J25)*(1-K25)) -> 1.3295095
B27: Median: | D27: =MEDIAN(D16:D25) -> 1.325 | E27: =MEDIAN(E16:E25) -> 1150 | F27: =MEDIAN(F16:F25) -> 0.21 | G27: =MEDIAN(G16:G25) -> 0 | H27: =MEDIAN(H16:H25) -> 0 | I27: =MEDIAN(I16:I25) -> 5400 | J27: =MEDIAN(J16:J25) -> 0.79 | K27: =MEDIAN(K16:K25) -> 0.23 | L27: =MEDIAN(L16:L25) -> 1.0380095
B29: =TEXT(Company_Name,"")& " - Levered Beta & WACC Calculation:" -> AeroVironment, Inc. - Levered Beta & WACC Calculation:
D30: Unlevered | G30: Preferred | I30: Equity | L30: Levered
C31: Ticker | D31: Beta | E31: Debt | F31: % Debt | G31: Stock | H31: % Preferred | I31: Value | J31: % Equity | K31: Tax Rate | L31: Beta
B32: Current Capital Structure: | C32: =Ticker -> AVAV | D32: =L27 -> 1.0380095 | E32: =(5638466-4418081)/Units -> 1220.385 | F32: =E32/($E32+$G32+$I32) -> 0.21643919 | G32: 0 | H32: =G32/($E32+$G32+$I32) -> 0 | I32: =4418081/Units -> 4418.081 | J32: =I32/($E32+$G32+$I32) -> 0.78356081 | K32: =Tax_Rate -> 0.16655 | L32: =D32*(1+((F32/J32)*(1-K32))) -> 1.2769798
B33: "Optimal" Capital Structure: | C33: =Ticker -> AVAV | D33: =L27 -> 1.0380095 | E33: =F33*($E32+$G32+$I32) -> 1184.0779 | F33: =F27 -> 0.21 | G33: =H33*($E32+$G32+$I32) -> 0 | H33: =H27 -> 0 | I33: =J33*($E32+$G32+$I32) -> 4454.3881 | J33: =J27 -> 0.79 | K33: =Tax_Rate -> 0.16655 | L33: =D33*(1+((F33/J33)*(1-K33))) -> 1.2679805
B35: Cost of Equity Based on Comparables, Current Capital Structure: | L35: =Risk_Free_Rate+L32*Equity_Risk_Premium -> 0.11143389
B36: Cost of Equity Based on Comparables, "Optimal" Capital Structure: | L36: =Risk_Free_Rate+L33*Equity_Risk_Premium -> 0.11093893
B37: Cost of Equity Based on Historical Beta: | L37: =Risk_Free_Rate+(Beta*Equity_Risk_Premium) -> 0.13195
B39: WACC = Cost of Equity * % Equity + Cost of Debt * % Debt * (1 - Tax Rate) + Cost of Preferred Stock * % Preferred Stock
B41: WACC, Current Capital Structure: | L41: =(L35*J32) + (Cost_of_Debt*F32*(1-Tax_Rate)) + (Cost_of_Preferred*H32) -> 0.098048509
B42: WACC, Current Capital Structure and Historical Cost of Equity: | L42: =(L37*J32) + (Cost_of_Debt*F32*(1-Tax_Rate)) + (Cost_of_Preferred*H32) -> 0.11412413
B43: WACC, "Optimal" Capital Structure: | L43: =(L36*J33) + (Cost_of_Debt*F33*(1-Tax_Rate)) + (Cost_of_Preferred*H33) -> 0.098055709
B45: Average WACC Produced by All Methods: | L45: =AVERAGE(L41:L43) -> 0.10340945

Sheet Public Comps
B2: Comparable Companies
B3: ($ in millions Except Per Share and Per Unit Data)
B5: =Inputs!#REF! -> #REF! | D5: =Inputs!#REF! -> #REF! | E5: =Inputs!#REF! -> #REF! | F5: =Inputs!#REF! -> #REF! | G5: =Inputs!#REF! -> #REF! | H5: =Inputs!#REF! -> #REF! | I5: =Inputs!#REF! -> #REF!
B6: Operating Statistics | E6: Capitalization
D7: Share | E7: Equity | F7: Enterprise | G7: Revenue | H7: EBITDA | I7: Reported Net Income | J7: EBITDA Margin
B8: Company Name | C8: Ticker | D8: Price | E8: Value | F8: Value | G8: =LTM -> LTM | H8: =LTM -> LTM | I8: =LTM -> LTM | J8: =LTM -> LTM
B9: Heico Corporation | C9: HEI | D9: 317.77 | E9: 37260 | F9: 39450 | G9: 4289 | H9: 1152 | I9: 642 | J9: =H9/G9 -> 0.26859408
B10: Teledyne Technologies Inc. | C10: TDY | D10: 526.82 | E10: 24240 | F10: 26240 | G10: 6005 | H10: 1393 | I10: 818 | J10: 0.23
B11: Curtiss-Wright Corporation | C11: CW | D11: 595.73 | E11: 20470 | F11: 21370 | G11: 3376 | H11: 759 | I11: 465 | J11: 0.22
B12: Textron Inc. | C12: TXT | D12: 80.81 | E12: 15000 | F12: 17210 | G12: 14237 | H12: 1497 | I12: 827 | J12: 0.11
B13: Kratos Defense & Security Solutions, Inc. | C13: KTOS | D13: 90.6 | E13: 12990 | F13: 12550 | G13: 1285 | H13: 89 | I13: 20 | J13: 0.07
B14: Huntington Ingalls Industries, Inc. | C14: HII | D14: 322.02 | E14: 12680 | F14: 15290 | G14: 12012 | H14: 1142 | I14: 569 | J14: 0.1
B15: Hexcel Corporation | C15: HXL | D15: 71.4 | E15: 6080 | F15: 6750 | G15: 1876 | H15: 242 | I15: 69 | J15: 0.13
B16: Spirit Aerosystems Holdigns, Inc. | C16: SPR | D16: 36.69 | E16: 4640 | F16: 9830 | G16: 6394 | H16: -2599 | I16: -1932 | J16: -0.41
B17: AAR Corporation | C17: AIR | D17: 84.21 | E17: 3250 | F17: 4270 | G17: 2858 | H17: 192 | I17: 29 | J17: 0.07
B18: Astronics Corporation | C18: ATRO | D18: 49.18 | E18: 1840 | F18: 2200 | G18: 831 | H18: 72 | I18: -3 | J18: 0.09
B20: Maximum | D20: =MAX(D9:D18) -> 595.73 | E20: =MAX(E9:E18) -> 37260 | F20: =MAX(F9:F18) -> 39450 | G20: =MAX(G9:G18) -> 14237 | H20: =MAX(H9:H18) -> 1497 | I20: =MAX(I9:I18) -> 827 | J20: =MAX(J9:J18) -> 0.26859408
B21: 75th Percentile | D21: =_xlfn.PERCENTILE.INC(D9:D18,0.75) -> 320.9575 | E21: =_xlfn.PERCENTILE.INC(E9:E18,0.75) -> 19102.5 | F21: =_xlfn.PERCENTILE.INC(F9:F18,0.75) -> 20330 | G21: =_xlfn.PERCENTILE.INC(G9:G18,0.75) -> 6296.75 | H21: =_xlfn.PERCENTILE.INC(H9:H18,0.75) -> 1149.5 | I21: =_xlfn.PERCENTILE.INC(I9:I18,0.75) -> 623.75 | J21: =_xlfn.PERCENTILE.INC(J9:J18,0.75) -> 0.1975
B22: Median | D22: =MEDIAN(D9:D18) -> 87.405 | E22: =MEDIAN(E9:E18) -> 12835 | F22: =MEDIAN(F9:F18) -> 13920 | G22: =MEDIAN(G9:G18) -> 3832.5 | H22: =MEDIAN(H9:H18) -> 500.5 | I22: =MEDIAN(I9:I18) -> 267 | J22: =MEDIAN(J9:J18) -> 0.105
B23: 25th Percentile | D23: =_xlfn.PERCENTILE.INC(D9:D18,0.25) -> 73.7525 | E23: =_xlfn.PERCENTILE.INC(E9:E18,0.25) -> 5000 | F23: =_xlfn.PERCENTILE.INC(F9:F18,0.25) -> 7520 | G23: =_xlfn.PERCENTILE.INC(G9:G18,0.25) -> 2121.5 | H23: =_xlfn.PERCENTILE.INC(H9:H18,0.25) -> 114.75 | I23: =_xlfn.PERCENTILE.INC(I9:I18,0.25) -> 22.25 | J23: =_xlfn.PERCENTILE.INC(J9:J18,0.25) -> 0.075
B24: Minimum | D24: =MIN(D9:D18) -> 36.69 | E24: =MIN(E9:E18) -> 1840 | F24: =MIN(F9:F18) -> 2200 | G24: =MIN(G9:G18) -> 831 | H24: =MIN(H9:H18) -> -2599 | I24: =MIN(I9:I18) -> -1932 | J24: =MIN(J9:J18) -> -0.41
B26: =Company_Name -> AeroVironment, Inc. | C26: =Ticker -> AVAV | D26: 369.91 | E26: 18470 | F26: 18610 | G26: =('AVAV-DCF'!I134+927184-377941)/Units -> 2212.555 | H26: =('AVAV-DCF'!I139-'AVAV-DCF'!I143-'AVAV-DCF'!I144+101513-63050)/Units -> 261.298 | I26: =(43619-84473-28709)/Units -> -69.563 | J26: =H26/G26 -> 0.11809786
B28: =Inputs!#REF! -> #REF! | D28: =Inputs!#REF! -> #REF! | E28: =Inputs!#REF! -> #REF! | F28: =Inputs!#REF! -> #REF! | G28: =Inputs!#REF! -> #REF! | H28: =Inputs!#REF! -> #REF! | I28: =Inputs!#REF! -> #REF!
B29: Valuation Statistics | E29: Capitalization | G29: EV/EBITDA | H29: EV/EBITDA | I29: P / E Multiple
D30: Share | E30: Equity | F30: Enterprise
B31: Company Name | D31: Price | E31: Value | F31: Value | G31: =LTM -> LTM | H31: =LTM -> LTM | I31: =LTM -> LTM
B32: =B9 -> Heico Corporation | D32: =D9 -> 317.77 | E32: =E9 -> 37260 | F32: =F9 -> 39450 | G32: =F9/G9 -> 9.1979482 | H32: =F9/H9 -> 34.244792 | I32: =F9/I9 -> 61.448598
B33: =B10 -> Teledyne Technologies Inc. | D33: =D10 -> 526.82 | E33: =E10 -> 24240 | F33: =F10 -> 26240 | G33: =F10/G10 -> 4.3696919 | H33: =F10/H10 -> 18.837042 | I33: =F10/I10 -> 32.07824
B34: =B11 -> Curtiss-Wright Corporation | D34: =D11 -> 595.73 | E34: =E11 -> 20470 | F34: =F11 -> 21370 | G34: =F11/G11 -> 6.3299763 | H34: =F11/H11 -> 28.155468 | I34: =F11/I11 -> 45.956989
B35: =B12 -> Textron Inc. | D35: =D12 -> 80.81 | E35: =E12 -> 15000 | F35: =F12 -> 17210 | G35: =F12/G12 -> 1.2088221 | H35: =F12/H12 -> 11.496326 | I35: =F12/I12 -> 20.810157
B36: =B13 -> Kratos Defense & Security Solutions, Inc. | D36: =D13 -> 90.6 | E36: =E13 -> 12990 | F36: =F13 -> 12550 | G36: =F13/G13 -> 9.766537 | H36: =F13/H13 -> 141.01124 | I36: =F13/I13 -> 627.5
B37: =B14 -> Huntington Ingalls Industries, Inc. | D37: =D14 -> 322.02 | E37: =E14 -> 12680 | F37: =F14 -> 15290 | G37: =F14/G14 -> 1.2728938 | H37: =F14/H14 -> 13.388792 | I37: =F14/I14 -> 26.871705
B38: =B15 -> Hexcel Corporation | D38: =D15 -> 71.4 | E38: =E15 -> 6080 | F38: =F15 -> 6750 | G38: =F15/G15 -> 3.598081 | H38: =F15/H15 -> 27.892562 | I38: =F15/I15 -> 97.826087
B39: =B16 -> Spirit Aerosystems Holdigns, Inc. | D39: =D16 -> 36.69 | E39: =E16 -> 4640 | F39: =F16 -> 9830 | G39: =F16/G16 -> 1.5373788 | H39: =F16/H16 -> -3.7822239 | I39: =F16/I16 -> -5.0879917
B40: =B17 -> AAR Corporation | D40: =D17 -> 84.21 | E40: =E17 -> 3250 | F40: =F17 -> 4270 | G40: =F17/G17 -> 1.4940518 | H40: =F17/H17 -> 22.239583 | I40: =F17/I17 -> 147.24138
B41: =B18 -> Astronics Corporation | D41: =D18 -> 49.18 | E41: =E18 -> 1840 | F41: =F18 -> 2200 | G41: =F18/G18 -> 2.6474128 | H41: =F18/H18 -> 30.555556 | I41: =F18/I18 -> -733.33333
B43: Maximum | D43: =MAX(D9:D18) -> 595.73 | E43: =MAX(E32:E41) -> 37260 | F43: =MAX(F32:F41) -> 39450 | G43: =MAX(G32:G41) -> 9.766537 | H43: =MAX(H32:H41) -> 141.01124 | I43: =MAX(I32:I41) -> 627.5
B44: 75th Percentile | D44: =_xlfn.PERCENTILE.INC(D9:D18,0.75) -> 320.9575 | E44: =_xlfn.PERCENTILE.INC(E32:E41,0.75) -> 19102.5 | F44: =_xlfn.PERCENTILE.INC(F32:F41,0.75) -> 20330 | G44: =_xlfn.PERCENTILE.INC(G32:G41,0.75) -> 5.8399052 | H44: =_xlfn.PERCENTILE.INC(H32:H41,0.75) -> 29.955534 | I44: =_xlfn.PERCENTILE.INC(I32:I41,0.75) -> 88.731715
B45: Median | D45: =MEDIAN(D9:D18) -> 87.405 | E45: =MEDIAN(E32:E41) -> 12835 | F45: =MEDIAN(F32:F41) -> 13920 | G45: =MEDIAN(G32:G41) -> 3.1227469 | H45: =MEDIAN(H32:H41) -> 25.066073 | I45: =MEDIAN(I32:I41) -> 39.017614
B46: 25th Percentile | D46: =_xlfn.PERCENTILE.INC(D9:D18,0.25) -> 73.7525 | E46: =_xlfn.PERCENTILE.INC(E32:E41,0.25) -> 5000 | F46: =_xlfn.PERCENTILE.INC(F32:F41,0.25) -> 7520 | G46: =_xlfn.PERCENTILE.INC(G32:G41,0.25) -> 1.5048835 | H46: =_xlfn.PERCENTILE.INC(H32:H41,0.25) -> 14.750854 | I46: =_xlfn.PERCENTILE.INC(I32:I41,0.25) -> 22.325544
...

Sheet MA-Comps
B2: Precedent Transactions
B3: =+'[1]JAZZ-DCF'!$B$3 -> ($ in Millions Except Per Share and Per Unit Data)
B5: =Company_Name&" - Comparable M&A Transactions" -> AeroVironment, Inc. - Comparable M&A Transactions | F5: Operating Metrics | H5: Valuation Multiples
E6: Transaction | H6: EV / | I6: EV /
E7: Enterprise | F7: LTM | G7: LTM | H7: LTM | I7: LTM
B8: Acquirer Name | C8: Target Name | D8: Date | E8: Value | F8: Revenue | G8: EBITDA | H8: Revenue | I8: EBITDA
A10: 1 | B10: TJC L.P. | C10: L3Harris Commercial Aviation Solutions (CAS) business | D10: 45256 | E10: 800 | F10: 525 | G10: 53.333333 | H10: =IFERROR($E10/F10,"NA") -> 1.5238095 | I10: =IFERROR($E10/G10,"NA") -> 15
A11: 2 | B11: Arcline Investment | C11: Kaman Corporation | D11: 45310 | E11: 1800 | F11: 769 | G11: 112 | H11: =IFERROR($E11/F11,"NA") -> 2.3407022 | I11: =IFERROR($E11/G11,"NA") -> 16.071429
A12: 3 | B12: Honeywell | C12: CAES Systems Holding LLC | D12: 45463 | E12: 1900 | F12: NA | G12: 135.71429 | H12: =IFERROR($E12/F12,"NA") -> NA | I12: =IFERROR($E12/G12,"NA") -> 14
A13: 4 | B13: Boeing | C13: Spirit Aerosystems | D13: 45474 | E13: 8400 | F13: 6446.9 | G13: -777.2 | H13: =IFERROR($E13/F13,"NA") -> 1.3029518 | I13: =IFERROR($E13/G13,"NA") -> -10.808029
A14: 5 | B14: Aerovironment, Inc. | C14: Blue Halo | D14: 45778 | E14: 4100 | F14: 842.685 | G14: 25.122 | H14: =IFERROR($E14/F14,"NA") -> 4.8654005 | I14: =IFERROR($E14/G14,"NA") -> 163.20357
A15: 6 | B15: TransDigm Group, Inc. | C15: Simmonds Precision Products | D15: 45838 | E15: 765 | F15: 350 | G15: NA | H15: =IFERROR($E15/F15,"NA") -> 2.1857143 | I15: =IFERROR($E15/G15,"NA") -> NA
A16: 7 | B16: Amphenol | C16: CommScope (CCS Segment) | D16: 45870 | E16: 10500 | F16: 3089.7 | G16: 761.1 | H16: =IFERROR($E16/F16,"NA") -> 3.3983882 | I16: =IFERROR($E16/G16,"NA") -> 13.795822
A17: 8 | B17: Advent International | C17: Coherent Corp (A&D Segment) | D17: 45882 | E17: 400 | F17: 20 | G17: NA | H17: =IFERROR($E17/F17,"NA") -> 20 | I17: =IFERROR($E17/G17,"NA") -> NA
A18: 9 | B18: Amphenol | C18: CommScope (OWN/DAS Segment) | D18: 45691 | E18: 2100 | F18: 1266 | G18: 339 | H18: =IFERROR($E18/F18,"NA") -> 1.6587678 | I18: =IFERROR($E18/G18,"NA") -> 6.1946903
C21: Maximum | E21: =MAX(E9:E19) -> 10500 | F21: =MAX(F9:F19) -> 6446.9 | G21: =MAX(G9:G19) -> 761.1 | H21: =MAX(H9:H19) -> 20 | I21: =MAX(I9:I19) -> 163.20357
C22: 75th Percentile | E22: =QUARTILE(E9:E19,3) -> 4100 | F22: =QUARTILE(F9:F19,3) -> 1721.925 | G22: =QUARTILE(G9:G19,3) -> 237.35714 | H22: =QUARTILE(H9:H19,3) -> 3.7651413 | I22: =QUARTILE(I9:I19,3) -> 15.535714
C23: Median | E23: =MEDIAN(E9:E19) -> 1900 | F23: =MEDIAN(F9:F19) -> 805.8425 | G23: =MEDIAN(G9:G19) -> 112 | H23: =MEDIAN(H9:H19) -> 2.2632082 | I23: =MEDIAN(I9:I19) -> 14
C24: 25th Percentile | E24: =QUARTILE(E9:E19,1) -> 800 | F24: =QUARTILE(F9:F19,1) -> 481.25 | G24: =QUARTILE(G9:G19,1) -> 39.227667 | H24: =QUARTILE(H9:H19,1) -> 1.6250282 | I24: =QUARTILE(I9:I19,1) -> 9.9952561
C25: Minimum | E25: =MIN(E9:E19) -> 400 | F25: =MIN(F9:F19) -> 20 | G25: =MIN(G9:G19) -> -777.2 | H25: =MIN(H9:H19) -> 1.3029518 | I25: =MIN(I9:I19) -> -10.808029

Sheet Synergy Calc
B2: Acquirer Name: | D2: Kratos Defense & Security Solutions
B3: Acquirer Ticker: | D3: KTOS
B5: (in $ m) | D5: KTOS
B6: Revenue: | D6: 1136.3
B7: COGS: | D7: 849.1
B8: Gross Profit: | D8: 287.2
B9: (gross margin %) | D9: =D8/D6 -> 0.25275015
B10: SG&A: | D10: 184.2
B11: R&D: | D11: 40.3
B12: Net Income: | D12: 16.3
B14: Revenue Synergies:
B15: Cross-Sell & Market Share Synergies:
B17: AVAV FY26E Revenue: | D17: (in $ m) | E17: ='AVAV-DCF'!J134/Units -> 1902.804
B19: Cross-sell uplift to AVAV | E19: 0.05
B20: Cross-sell uplift to KTOS | E20: 0.03
B22: Total Uplift: | D22: (in $ m) | E22: =E19*E17 + E20*D6 -> 129.2292
B24: Backlog Portfolio Synergies:
B26: AVAV backlog: | D26: (in $ m) | E26: 1090
B27: KTOS backlog: | D27: (in $ m) | E27: 1350
B29: Backlog conversion uplift: | E29: 0.03
B31: Backlog Conversion: | D31: (in $ m) | E31: =(E26+E27)*E29 -> 73.2
B33: New Integrated Offerings:
B35: Incremental Revenue Uplift: | E35: 0.02
B37: Incremental Revenue: | D37: (in $ m) | E37: =E35*SUM(E17,D6) -> 60.78208
B39: Cost Synergies:
B40: SG&A Consolidation:
B42: AVAV SG&A: | D42: (in $ m) | E42: ='AVAV-DCF'!I144/Units -> 115.855
B44: SG&A elimination: | E44: 0.18
B46: SG&A Savings: | D46: (in $ m) | E46: =E44*(E42+D10) -> 54.0099
B48: R&D Rationalisation:
B50: AVAV R&D: | D50: (in $ m) | E50: ='AVAV-DCF'!J144/Units -> 123.68226
B52: R&D Reduction: | E52: 0.1
B54: R&D Savings: | D54: (in $ m) | E54: =E52*(E50+D11) -> 16.398226
B56: Procurement & Supply Chain:
B58: AVAV COGS: | D58: (in $ m) | E58: ='AVAV-DCF'!J137/Units -> 1147.2208
B60: Procurement Cost Reduction: | E60: 0.025
B62: Procurement Savings: | D62: (in $ m) | E62: =E60*(E58+D7) -> 49.908021
B64: Manufacturing/Facilities Rationalisation:
B66: Duplication Reductions: | D66: (in $ m) | E66: 15
B68: Combined EBITDA Impact:
...

Sheet ValSum
B2: ="Valuation Summary - "&TEXT(Company_Name,"")&" - "&Scenario&" Case" -> Valuation Summary - AeroVironment, Inc. - Base Case
B3: ($ in Millions Except Per Share and Per Unit Data)
B5: ="Valuation Statistics - "&TEXT(Company_Name,"") -> Valuation Statistics - AeroVironment, Inc. | C5: Range of Valuation Multiples / Premiums | I5: Implied Per-Share Value Range
D7: 75th | F7: 25th | H7: Applicable | J7: 25th | L7: 75th
C8: Maximum | D8: Percentile | E8: Median | F8: Percentile | G8: Minimum | H8: Company | I8: Minimum | J8: Percentile | K8: Median | L8: Percentile | M8: Maximum
B9: Methodology Name | C9: Multiple | D9: Multiple | E9: Multiple | F9: Multiple | G9: Multiple | H9: Figure | I9: Multiple | J9: Multiple | K9: Multiple | L9: Multiple | M9: Multiple
B11: Public Company Comparables:
B12: =TEXT(LTM,"mm/dd/yyyy")&" EV / Revenue:" -> LTM EV / Revenue: | C12: {=TRANSPOSE('Public Comps'!G43:G47)} -> 9.766537 | D12: 5.8399052 | E12: 3.1227469 | F12: 1.5048835 | G12: 1.2088221 | H12: {=TRANSPOSE('Public Comps'!G26:I26)} -> 2212.555 | I12: =((H12*$G12)+$E$31)/$E$33 -> 96.939365 | J12: =(($H12*F12)+$E$31)/$E$33 -> 109.09194 | K12: =(($H12*E12)+$E$31)/$E$33 -> 175.50113 | L12: =(($H12*D12)+$E$31)/$E$33 -> 287.0336 | M12: =(($H12*C12)+$E$31)/$E$33 -> 448.21188
B13: =TEXT(LTM,"mm/dd/yyyy")&" EV / EBITDA:" -> LTM EV / EBITDA: | C13: {=TRANSPOSE('Public Comps'!H43:H47)} -> 141.01124 | D13: 29.955534 | E13: 25.066073 | F13: 14.750854 | G13: -3.7822239 | H13: 261.298 | I13: 0 | J13: =(($H13*F13)+$E$31)/$E$33 -> 118.82678 | K13: =(($H13*E13)+$E$31)/$E$33 -> 168.83102 | L13: =(($H13*D13)+$E$31)/$E$33 -> 192.53326 | M13: =(($H13*C13)+$E$31)/$E$33 -> 730.88885
H14: -69.563
B15: Precedent Transactions:
B16: =TEXT(LTM,"mm/dd/yyyy")&" EV / Revenue:" -> LTM EV / Revenue: | C16: {=TRANSPOSE('MA-Comps'!H21:H25)} -> 20 | D16: 3.7651413 | E16: 2.2632082 | F16: 1.6250282 | G16: 1.3029518 | H16: {=TRANSPOSE('Public Comps'!G26:I26)} -> 2212.555 | I16: =((H16*$G16)+$E$31)/$E$33 -> 100.80315 | J16: =(($H16*F16)+$E$31)/$E$33 -> 114.02357 | K16: =(($H16*E16)+$E$31)/$E$33 -> 140.21925 | L16: =(($H16*D16)+$E$31)/$E$33 -> 201.86979 | M16: =(($H16*C16)+$E$31)/$E$33 -> 868.26961
B17: =TEXT(LTM,"mm/dd/yyyy")&" EV / EBITDA:" -> LTM EV / EBITDA: | C17: {=TRANSPOSE('MA-Comps'!I21:I25)} -> 163.20357 | D17: 15.535714 | E17: 14 | F17: 9.9952561 | G17: -10.808029 | H17: 261.298 | I17: =((H17*$G17)+$E$31)/$E$33 -> -5.0729122 | J17: =(($H17*F17)+$E$31)/$E$33 -> 95.773461 | K17: =(($H17*E17)+$E$31)/$E$33 -> 115.18693 | L17: =(($H17*D17)+$E$31)/$E$33 -> 122.63149 | M17: =(($H17*C17)+$E$31)/$E$33 -> 838.46879
H18: -69.563
B19: Discounted Cash Flow Analysis:
B20: =TEXT('AVAV-DCF'!D201,"0.00%")&" - "&TEXT('AVAV-DCF'!D209,"0.00%")&" WACC, "&TEXT('AVAV-DCF'!E200,"0.00%")&" - "&TEXT('AVAV-DCF'!M200,"0.00%")&" Terminal FCF Growth Rate:" -> 8.50% - 12.50% WACC, 1.00% - 3.00% Terminal FCF Growth Rate: | I20: ='AVAV-DCF'!E209 -> 205.25974 | J20: ='AVAV-DCF'!G207 -> 214.49301 | K20: ='AVAV-DCF'!I205 -> 224.82824 | L20: ='AVAV-DCF'!K203 -> 236.47611 | M20: ='AVAV-DCF'!M201 -> 249.70474
B22: Implied Equity Value Calculations: | H22: Implied Enterprise Value or Equity Value at a Range of Multiples:
B24: Implied Enterprise Value: | E24: =J27 -> 2611.7404 | G24: Enterprise Value --> | I24: =H12*G12 -> 2674.5853 | J24: =H12*F12 -> 3329.6376 | K24: =H12*E12 -> 6909.2492 | L24: =H12*D12 -> 12921.111 | M24: =H12*C12 -> 21609
B25: (+) Cash & Cash-Equivalents: | E25: ='AVAV-DCF'!G106 -> 588.48 | G25: Enterprise Value --> | I25: =H13*G13 -> -988.28755 | J25: =H13*F13 -> 3854.3687 | K25: =H13*E13 -> 6549.7147 | L25: =H13*D13 -> 7827.321 | M25: =H13*C13 -> 36845.954
B26: (+) Equity Investments: | E26: ='AVAV-DCF'!G107 -> 80.97 | G26: Enterprise Value --> | I26: =H16*G16 -> 2882.8525 | J26: =H16*F16 -> 3595.4643 | K26: =H16*E16 -> 5007.4727 | L26: =H16*D16 -> 8330.5821 | M26: =H16*C16 -> 44251.1
B27: (+) Other Non-Core Assets, Net: | E27: ='AVAV-DCF'!G108 -> 234.491 | G27: Enterprise Value --> | I27: =H17*G17 -> -2824.1163 | J27: =H17*F17 -> 2611.7404 | K27: =H17*E17 -> 3658.172 | L27: =H17*D17 -> 4059.4511 | M27: =H17*C17 -> 42644.766
B28: (+) Net Operating Losses: | E28: ='AVAV-DCF'!G109 -> -73.188
B29: (-) Debt & Capital Leases | E29: ='AVAV-DCF'!G110 -> 840.764
B30: (-) Restructuring & Other Liabilities: | E30: ='AVAV-DCF'!G111 -> 51.055
B31: Implied Equity Value: | E31: =+SUM(E24:E28)-SUM(E29:E30) -> 2550.6744
B33: Diluted Shares Outstanding: | E33: ='Share Dilution Calc'!H27 -> 53.902352
B35: Implied Share Price from Selected Valuation Multiple: | E35: =+E31/E33 -> 47.32028
B36: Premium / (Discount) to Current: | E36: =E35/Share_Price - 1 -> -0.87207623
D38: Exercise
B39: Type: | C39: Number: | D39: Price: | E39: Dilution:
B40: Options A: | C40: ='AVAV-DCF'!E121 -> 5.275826 | D40: ='AVAV-DCF'!F121 -> 280 | E40: ='AVAV-DCF'!G121 -> 1.2823376
B41: Convertible Bonds: | C41: ='AVAV-DCF'!E122 -> 0.7475 | D41: ='AVAV-DCF'!F122 -> 322.4 | E41: ='AVAV-DCF'!G122 -> 2.3185484
B42: RSUs: | C42: ='AVAV-DCF'!E123 -> 0.37416 | D42: ='AVAV-DCF'!F123 -> 0 | E42: ='AVAV-DCF'!G123 -> 0.37416
B43: Total: | E43: =SUM(E40:E42) -> 3.975046

Sheet ValGraph
I32: Min | J32: 25th | K32: Median | L32: 75th | M32: Max | N32: Min Point | O32: 25th Point | P32: Median Point | Q32: 75th Point | R32: Max Point
B34: =+ValSum!B20 -> 8.50% - 12.50% WACC, 1.00% - 3.00% Terminal FCF Growth Rate: | I34: =ValSum!I20 -> 205.25974 | J34: =ValSum!J20 -> 214.49301 | K34: =ValSum!K20 -> 224.82824 | L34: =ValSum!L20 -> 236.47611 | M34: =ValSum!M20 -> 249.70474 | N34: =I34 -> 205.25974 | O34: =J34-I34 -> 9.2332723 | P34: =K34-J34 -> 10.335225 | Q34: =L34-K34 -> 11.647877 | R34: =M34-L34 -> 13.228629
B36: =+ValSum!B17 -> LTM EV / EBITDA: | I36: =ValSum!I17 -> -5.0729122 | J36: =ValSum!J17 -> 95.773461 | K36: =ValSum!K17 -> 115.18693 | L36: =ValSum!L17 -> 122.63149 | M36: =ValSum!M17 -> 838.46879 | N36: =I36 -> -5.0729122 | O36: =J36-I36 -> 100.84637 | P36: =K36-J36 -> 19.413468 | Q36: =L36-K36 -> 7.4445559 | R36: =M36-L36 -> 715.83731
B37: =+ValSum!B16 -> LTM EV / Revenue: | I37: =ValSum!I16 -> 100.80315 | J37: =ValSum!J16 -> 114.02357 | K37: =ValSum!K16 -> 140.21925 | L37: =ValSum!L16 -> 201.86979 | M37: =ValSum!M16 -> 868.26961 | N37: =I37 -> 100.80315 | O37: =J37-I37 -> 13.22042 | P37: =K37-J37 -> 26.195674 | Q37: =L37-K37 -> 61.650545 | R37: =M37-L37 -> 666.39982
B39: =+ValSum!B13 -> LTM EV / EBITDA: | I39: =ValSum!I13 -> 0 | J39: =ValSum!J13 -> 118.82678 | K39: =ValSum!K13 -> 168.83102 | L39: =ValSum!L13 -> 192.53326 | M39: =ValSum!M13 -> 730.88885 | N39: =I39 -> 0 | O39: =J39-I39 -> 118.82678 | P39: =K39-J39 -> 50.004236 | Q39: =L39-K39 -> 23.702238 | R39: =M39-L39 -> 538.3556
B40: =+ValSum!B12 -> LTM EV / Revenue: | I40: =ValSum!I12 -> 96.939365 | J40: =ValSum!J12 -> 109.09194 | K40: =ValSum!K12 -> 175.50113 | L40: =ValSum!L12 -> 287.0336 | M40: =ValSum!M12 -> 448.21188 | N40: =I40 -> 96.939365 | O40: =J40-I40 -> 12.152573 | P40: =K40-J40 -> 66.409192 | Q40: =L40-K40 -> 111.53247 | R40: =M40-L40 -> 161.17829

Sheet Inputs
B2: Cell Inputs and Lookup Cells for Use in Public Comps:
B4: Labels for Comparables:
B6: Last Twelve Months | E6: LTM
B7: Forward Year 1 | E7: =EOMONTH(Hist_Year,12) -> 46142
B8: Forward Year 2 | E8: =EOMONTH(Forward_Year_1,12) -> 46507
B9: Forward Year 3 | E9: =EOMONTH(Forward_Year_2,12) -> 46873
